<?xml version="1.0"?>

<robot
  name="komodo2">
  <link
    name="base_link">
    <inertial>
      <origin
        xyz="0.0265371254582772 0.000242403640172173 0.0501704404394482"
        rpy="0 0 0" />
      <mass
        value="1.70660108565618" />
      <inertia
        ixx="0.0285642304866605"
        ixy="-0.000201185394992359"
        ixz="-0.000317415309478303"
        iyy="0.0639136623858303"
        iyz="-1.60880321018346E-06"
        izz="0.07625494098217" />
    </inertial>
    <visual>
      <origin
        xyz="0 0 0"
        rpy="0 0 0" />
      <geometry>
        <mesh
          filename="package://komodo2/meshes/base.STL" />
      </geometry>
      <material
        name="">
        <color
          rgba="0.792156862745098 0.819607843137255 0.933333333333333 1" />
      </material>
    </visual>
    <collision>
      <origin
        xyz="0 0 0"
        rpy="0 0 0" />
      <geometry>
        <mesh
          filename="package://komodo2/meshes/base.STL" />
      </geometry>
    </collision>
  </link>
  <link
    name="footprint_link" />
  <joint
    name="footprint_joint"
    type="fixed">
    <origin
      xyz="0 -0.00349999999999995 -0.126"
      rpy="0 0 0" />
    <parent
      link="base_link" />
    <child
      link="footprint_link" />
    <axis
      xyz="0 0 0" />
  </joint>
  <link
    name="laser_link" />
  <joint
    name="laser_joint"
    type="fixed">
    <origin
      xyz="0.233497501055752 0 0.141334654748157"
      rpy="0 0 0" />
    <parent
      link="base_link" />
    <child
      link="laser_link" />
    <axis
      xyz="0 0 0" />
  </joint>
  <link
    name="front_cam_link" />
  <joint
    name="front_cam_joint"
    type="fixed">
    <origin
      xyz="0.257250027816762 0.0875000000000053 0.1"
      rpy="0 0 0" />
    <parent
      link="base_link" />
    <child
      link="front_cam_link" />
    <axis
      xyz="0 0 0" />
  </joint>
  <link
    name="depth_cam_link" />
  <joint
    name="depth_cam_joint"
    type="fixed">
    <origin
      xyz="0.262250027816762 0.00102830288238904 0.0635000000000002"
      rpy="0 0 0" />
    <parent
      link="base_link" />
    <child
      link="depth_cam_link" />
    <axis
      xyz="0 0 0" />
  </joint>
  <link
    name="right_urf_link" />
  <joint
    name="right_urf_joint"
    type="fixed">
    <origin
      xyz="-0.0225419326154781 -0.137249999999995 0.138101776066688"
      rpy="0 0 0" />
    <parent
      link="base_link" />
    <child
      link="right_urf_link" />
    <axis
      xyz="0 0 0" />
  </joint>
  <link
    name="rear_urf_link" />
  <joint
    name="rear_urf_joint"
    type="fixed">
    <origin
      xyz="-0.267499972183238 0.00022860000000516 0.1175936"
      rpy="0 0 3.14159265358979" />
    <parent
      link="base_link" />
    <child
      link="rear_urf_link" />
    <axis
      xyz="0 0 0" />
  </joint>
  <link
    name="left_urf_link" />
  <joint
    name="left_urf_joint"
    type="fixed">
    <origin
      xyz="-0.0220847326154781 0.137250000000005 0.138101776066688"
      rpy="0 0 0" />
    <parent
      link="base_link" />
    <child
      link="left_urf_link" />
    <axis
      xyz="0 0 0" />
  </joint>
  <link
    name="front_left_wheel_link">
    <inertial>
      <origin
        xyz="1.06542009199739E-05 0.00115773372814759 -1.501840532905E-05"
        rpy="0 0 0" />
      <mass
        value="2.68204072018496" />
      <inertia
        ixx="0.0127575754327221"
        ixy="1.06323698473979E-06"
        ixz="1.32400044989008E-06"
        iyy="0.0232771977739384"
        iyz="-1.70158762992046E-06"
        izz="0.0127565430134399" />
    </inertial>
    <visual>
      <origin
        xyz="0 0 0"
        rpy="0 0 0" />
      <geometry>
        <mesh
          filename="package://komodo2/meshes/wheel.STL" />
      </geometry>
      <material
        name="">
        <color
          rgba="0.792156862745098 0.819607843137255 0.933333333333333 1" />
      </material>
    </visual>
    <collision>
      <origin
        xyz="0 0 0"
        rpy="0 0 0" />
      <geometry>
        <mesh
          filename="package://komodo2/meshes/wheel.STL" />
      </geometry>
    </collision>
  </link>
  <joint
    name="front_left_wheel_joint"
    type="continuous">
    <origin
      xyz="0.173999999999995 0.1869 0"
      rpy="0 0 0" />
    <parent
      link="base_link" />
    <child
      link="front_left_wheel_link" />
    <axis
      xyz="0 1 0" />
  </joint>
  <link
    name="rear_left_wheel_link">
    <inertial>
      <origin
        xyz="0.33001065420092 0.00115773372814756 -1.50184053290035E-05"
        rpy="0 0 0" />
      <mass
        value="2.68204072018496" />
      <inertia
        ixx="0.0127575754327221"
        ixy="1.06323698473982E-06"
        ixz="1.32400044989004E-06"
        iyy="0.0232771977739384"
        iyz="-1.70158762992044E-06"
        izz="0.0127565430134399" />
    </inertial>
    <visual>
      <origin
        xyz="0 0 0"
        rpy="0 0 0" />
      <geometry>
        <mesh
          filename="package://komodo2/meshes/wheel.STL" />
      </geometry>
      <material
        name="">
        <color
          rgba="0.792156862745098 0.819607843137255 0.933333333333333 1" />
      </material>
    </visual>
    <collision>
      <origin
        xyz="0 0 0"
        rpy="0 0 0" />
      <geometry>
        <mesh
          filename="package://komodo2/meshes/wheel.STL" />
      </geometry>
    </collision>
  </link>
  <joint
    name="rear_left_wheel_joint"
    type="continuous">
    <origin
      xyz="-0.156000000000005 0.1869 0"
      rpy="0 0 0" />
    <parent
      link="base_link" />
    <child
      link="rear_left_wheel_link" />
    <axis
      xyz="0 1 0" />
  </joint>
  <link
    name="front_right_wheel_link">
    <inertial>
      <origin
        xyz="1.06542009198907E-05 0.374957733728148 -1.50184053290484E-05"
        rpy="0 0 0" />
      <mass
        value="2.68204072018496" />
      <inertia
        ixx="0.0127575754327221"
        ixy="1.0632369847399E-06"
        ixz="1.3240004498902E-06"
        iyy="0.0232771977739384"
        iyz="-1.70158762992054E-06"
        izz="0.0127565430134399" />
    </inertial>
    <visual>
      <origin
        xyz="0 0 0"
        rpy="0 0 0" />
      <geometry>
        <mesh
          filename="package://komodo2/meshes/wheel.STL" />
      </geometry>
      <material
        name="">
        <color
          rgba="0.792156862745098 0.819607843137255 0.933333333333333 1" />
      </material>
    </visual>
    <collision>
      <origin
        xyz="0 0 0"
        rpy="0 0 0" />
      <geometry>
        <mesh
          filename="package://komodo2/meshes/wheel.STL" />
      </geometry>
    </collision>
  </link>
  <joint
    name="front_right_wheel_joint"
    type="continuous">
    <origin
      xyz="0.173999999999995 -0.1869 0"
      rpy="0 0 0" />
    <parent
      link="base_link" />
    <child
      link="front_right_wheel_link" />
    <axis
      xyz="0 1 0" />
  </joint>
  <link
    name="rear_right_wheel_link">
    <inertial>
      <origin
        xyz="0.33001065420092 0.374957733728148 -1.50184053290297E-05"
        rpy="0 0 0" />
      <mass
        value="2.68204072018496" />
      <inertia
        ixx="0.0127575754327221"
        ixy="1.06323698473987E-06"
        ixz="1.32400044989002E-06"
        iyy="0.0232771977739384"
        iyz="-1.70158762992054E-06"
        izz="0.0127565430134399" />
    </inertial>
    <visual>
      <origin
        xyz="0 0 0"
        rpy="0 0 0" />
      <geometry>
        <mesh
          filename="package://komodo2/meshes/wheel.STL" />
      </geometry>
      <material
        name="">
        <color
          rgba="0.792156862745098 0.819607843137255 0.933333333333333 1" />
      </material>
    </visual>
    <collision>
      <origin
        xyz="0 0 0"
        rpy="0 0 0" />
      <geometry>
        <mesh
          filename="package://komodo2/meshes/wheel.STL" />
      </geometry>
    </collision>
  </link>
  <joint
    name="rear_right_wheel_joint"
    type="continuous">
    <origin
      xyz="-0.156000000000005 -0.1869 0"
      rpy="0 0 0" />
    <parent
      link="base_link" />
    <child
      link="rear_right_wheel_link" />
    <axis
      xyz="0 1 0" />
  </joint>
</robot>